Workbook
Name diagram_changer: IF('Best Country'!$L$3="Map", 'Best Country (diagrams)'!$A$1:$G$19, 'Best Country (diagrams)'!$A$22:$G$40)

Sheet Best Country
A1: Best Country
A3: Move the sliders to set your priorities | G3: Continent: | H3: Europe | K3: Diagram type: | L3: Map | O3: =G6&" (0-100)" -> Finland (0-100)
A5: Low cost of living (including rent) | G5: According to you, the best country is | K5: Your overall rating (0-100) | O5: Cost of living
A6: =E6 -> 6 | E6: 6 | G6: ='Best Country (help)'!A15 -> Finland | K6: ='Best Country (help)'!B15 -> 73.26 | O6: {=ROUND(_xlfn.XLOOKUP('Best Country (help)'!A15,_xlfn.ANCHORARRAY( 'Best Country (help)'!H5), 'Best Country (help)'!S5:S238)*100, 'Best Country (help)'!B1)} -> 58.67
A8: High income | O8: Income
A9: =E9 -> 7 | E9: 7 | O9: {=ROUND(_xlfn.XLOOKUP('Best Country (help)'!A15,_xlfn.ANCHORARRAY( 'Best Country (help)'!H5), 'Best Country (help)'!Q5:Q238)*100, 'Best Country (help)'!B1)} -> 20.63
A11: Low income inequality | O11: Income inequality
A12: =E12 -> 5 | E12: 5 | O12: {=ROUND(_xlfn.XLOOKUP('Best Country (help)'!A15,_xlfn.ANCHORARRAY( 'Best Country (help)'!H5), 'Best Country (help)'!K5:K238)*100, 'Best Country (help)'!B1)} -> 90.12
A14: High human development | O14: Development
A15: =E15 -> 8 | E15: 8 | O15: {=ROUND(_xlfn.XLOOKUP('Best Country (help)'!A15,_xlfn.ANCHORARRAY( 'Best Country (help)'!H5), 'Best Country (help)'!M5:M238)*100, 'Best Country (help)'!B1)} -> 95.89
A17: High life expectancy | O17: Life Expectancy
A18: =E18 -> 5 | E18: 5 | O18: {=ROUND(_xlfn.XLOOKUP('Best Country (help)'!A15,_xlfn.ANCHORARRAY( 'Best Country (help)'!H5), 'Best Country (help)'!O5:O238)*100, 'Best Country (help)'!B1)} -> 87.85
A20: High safety | O20: Safety
A21: =E21 -> 4 | E21: 4 | O21: {=ROUND(_xlfn.XLOOKUP('Best Country (help)'!A15,_xlfn.ANCHORARRAY( 'Best Country (help)'!H5), 'Best Country (help)'!U5:U238)*100, 'Best Country (help)'!B1)} -> 82.19
A23: Good health care | O23: Health Care
A24: =E24 -> 3 | E24: 3 | O24: {=ROUND(_xlfn.XLOOKUP('Best Country (help)'!A15,_xlfn.ANCHORARRAY( 'Best Country (help)'!H5), 'Best Country (help)'!W5:W238)*100, 'Best Country (help)'!B1)} -> 20.25
A26: High happieness | O26: Happieness
A27: =E27 -> 9 | E27: 9 | O27: {=ROUND(_xlfn.XLOOKUP('Best Country (help)'!A15,_xlfn.ANCHORARRAY( 'Best Country (help)'!H5), 'Best Country (help)'!Y5:Y238)*100, 'Best Country (help)'!B1)} -> 100

Sheet Best Country (help)
A1: Digits to round: | B1: 2 | G1: Continent | H1: Country | I1: Overall rating | J1: Gini | K1: 0-100% | L1: HDI | M1: 0-100% | N1: Life expectancy | O1: 0-100% | P1: GDP per capita | Q1: 0-100% | R1: Cost of living (including rent) | S1: 0-100% | T1: Safety | U1: 0-100% | V1: Health Care | W1: 0-100% | X1: Happieness | Y1: 0-100%
D2: Clean ratings x100 | H2: Max | J2: =MAX(_xlfn.ANCHORARRAY(J5)) -> 0.6302572 | L2: =MAX(_xlfn.ANCHORARRAY(L5)) -> 0.972 | N2: =MAX(_xlfn.ANCHORARRAY(N5)) -> 85.706 | P2: =MAX(_xlfn.ANCHORARRAY(P5)) -> 260696 | R2: =MAX(_xlfn.ANCHORARRAY(R5)) -> 94.3 | T2: =MAX(_xlfn.ANCHORARRAY(T5)) -> 85.2 | V2: =MAX(_xlfn.ANCHORARRAY(V5)) -> 87 | X2: =MAX(_xlfn.ANCHORARRAY(X5)) -> 7.736
A3: Continents | B3: Diagram Type | D3: Country | E3: Rating | H3: Min | J3: =MIN(_xlfn.ANCHORARRAY(J5)) -> 0.24078926 | L3: =MIN(_xlfn.ANCHORARRAY(L5)) -> 0.388 | N3: =MIN(_xlfn.ANCHORARRAY(N5)) -> 54.462 | P3: =MIN(_xlfn.ANCHORARRAY(P5)) -> 328 | R3: =MIN(_xlfn.ANCHORARRAY(R5)) -> 11.3 | T3: =MIN(_xlfn.ANCHORARRAY(T5)) -> 19.5 | V3: =MIN(_xlfn.ANCHORARRAY(V5)) -> 39.6 | X3: =MIN(_xlfn.ANCHORARRAY(X5)) -> 1.364
A5: World | B5: Map | D5: {=_xlfn._xlws.FILTER(_xlfn.ANCHORARRAY(H5), I5:I238<>"")} -> Albania | E5: {=ROUND(_xlfn._xlws.FILTER(I5:I238*100, I5:I238<>""), B1)} -> 62.38 | G5: {=main_table[Continent]} -> Asia | H5: {=main_table[Country]} -> Afghanistan | I5: =IFERROR(( K5*'Best Country'!$E$12+ M5*'Best Country'!$E$15+ O5*'Best Country'!$E$18+ Q5*'Best Country'!$E$9+ S5*'Best Country'!$E$6+ U5*'Best Country'!$E$21+ W5*'Best Country'!$E$24+ Y5*'Best Country'!$E$27 )/SUM('Best Country'!$E$5:$E$28), "") | J5: {=IF(main_table[Gini-Coefficient (2021 prices; income or consumption consolid)]<>0, main_table[Gini-Coefficient (2021 prices; income or consumption consolid)], "")} | K5: =IFERROR(1-(J5-J$3)/(J$2-J$3), "") | L5: {=IF(main_table[HDI (2023)]<>0, main_table[HDI (2023)], "")} -> 0.496 | M5: =IFERROR((L5-L$3)/(L$2-L$3), "") -> 0.18493151 | N5: {=IF(main_table[Years of life expectancy at birth (2023)]<>0, main_table[Years of life expectancy at birth (2023)], "")} -> 66.035 | O5: =IFERROR((N5-N$3)/(N$2-N$3), "") -> 0.37040712 | P5: {=IF(main_table[GDP per capita (USD)]<>0, main_table[GDP per capita (USD)], "")} -> 374 | Q5: =IFERROR((P5-P$3)/(P$2-P$3), "") -> 0.00017667302 | R5: {=IF(main_table[Cost of Living Plus Rent Index]<>0, main_table[Cost of Living Plus Rent Index], "")} -> 11.6 | S5: =IFERROR(1-(R5-R$3)/(R$2-R$3), "") -> 0.99638554 | T5: {=IF(main_table[Safety Index], main_table[Safety Index], "")} | U5: =IFERROR((T5-T$3)/(T$2-T$3), "") | V5: {=IF(main_table[Health Care Index]<>0, main_table[Health Care Index], "")} | W5: =IFERROR(1-(V5-V$3)/(V$2-V$3), "") | X5: {=IF(main_table[Word Happieness Report (life evaluation; 3-year-average)]<>0, main_table[Word Happieness Report (life evaluation; 3-year-average)], "")} -> 1.364 | Y5: =IFERROR((X5-X$3)/(X$2-X$3), "") -> 0
A6: Africa | B6: Bars | D6: Argentina | E6: 58.52 | G6: Europe | H6: Albania | I6: =IFERROR(( K6*'Best Country'!$E$12+ M6*'Best Country'!$E$15+ O6*'Best Country'!$E$18+ Q6*'Best Country'!$E$9+ S6*'Best Country'!$E$6+ U6*'Best Country'!$E$21+ W6*'Best Country'!$E$24+ Y6*'Best Country'!$E$27 )/SUM('Best Country'!$E$5:$E$28), "") -> 0.62384718 | J6: 0.2941963 | K6: =IFERROR(1-(J6-J$3)/(J$2-J$3), "") -> 0.86287179 | L6: 0.81 | M6: =IFERROR((L6-L$3)/(L$2-L$3), "") -> 0.72260274 | N6: 79.602 | O6: =IFERROR((N6-N$3)/(N$2-N$3), "") -> 0.80463449 | P6: 10237 | Q6: =IFERROR((P6-P$3)/(P$2-P$3), "") -> 0.038057672 | R6: 31.3 | S6: =IFERROR(1-(R6-R$3)/(R$2-R$3), "") -> 0.75903614 | T6: 55.8 | U6: =IFERROR((T6-T$3)/(T$2-T$3), "") -> 0.55251142 | V6: 48.2 | W6: =IFERROR(1-(V6-V$3)/(V$2-V$3), "") -> 0.8185654 | X6: 5.411 | Y6: =IFERROR((X6-X$3)/(X$2-X$3), "") -> 0.63512241
A7: Asia | D7: Armenia | E7: 63.35 | G7: Africa | H7: Algeria | I7: =IFERROR(( K7*'Best Country'!$E$12+ M7*'Best Country'!$E$15+ O7*'Best Country'!$E$18+ Q7*'Best Country'!$E$9+ S7*'Best Country'!$E$6+ U7*'Best Country'!$E$21+ W7*'Best Country'!$E$24+ Y7*'Best Country'!$E$27 )/SUM('Best Country'!$E$5:$E$28), "") | J7: 0.27615732 | K7: =IFERROR(1-(J7-J$3)/(J$2-J$3), "") -> 0.90918878 | L7: 0.763 | M7: =IFERROR((L7-L$3)/(L$2-L$3), "") -> 0.64212329 | N7: 76.261 | O7: =IFERROR((N7-N$3)/(N$2-N$3), "") -> 0.69770196 | P7: 5668 | Q7: =IFERROR((P7-P$3)/(P$2-P$3), "") -> 0.020509433 | R7: 16.7 | S7: =IFERROR(1-(R7-R$3)/(R$2-R$3), "") -> 0.93493976 | U7: =IFERROR((T7-T$3)/(T$2-T$3), "") | W7: =IFERROR(1-(V7-V$3)/(V$2-V$3), "") | X7: 5.571 | Y7: =IFERROR((X7-X$3)/(X$2-X$3), "") -> 0.66023227
A8: Europe | D8: Australia | E8: 68.13 | G8: Oceania | H8: American Samoa | I8: =IFERROR(( K8*'Best Country'!$E$12+ M8*'Best Country'!$E$15+ O8*'Best Country'!$E$18+ Q8*'Best Country'!$E$9+ S8*'Best Country'!$E$6+ U8*'Best Country'!$E$21+ W8*'Best Country'!$E$24+ Y8*'Best Country'!$E$27 )/SUM('Best Country'!$E$5:$E$28), "") | K8: =IFERROR(1-(J8-J$3)/(J$2-J$3), "") | M8: =IFERROR((L8-L$3)/(L$2-L$3), "") | O8: =IFERROR((N8-N$3)/(N$2-N$3), "") | Q8: =IFERROR((P8-P$3)/(P$2-P$3), "") | S8: =IFERROR(1-(R8-R$3)/(R$2-R$3), "") | U8: =IFERROR((T8-T$3)/(T$2-T$3), "") | W8: =IFERROR(1-(V8-V$3)/(V$2-V$3), "") | Y8: =IFERROR((X8-X$3)/(X$2-X$3), "")
A9: North America | D9: Austria | E9: 68.5 | G9: Europe | H9: Andorra | I9: =IFERROR(( K9*'Best Country'!$E$12+ M9*'Best Country'!$E$15+ O9*'Best Country'!$E$18+ Q9*'Best Country'!$E$9+ S9*'Best Country'!$E$6+ U9*'Best Country'!$E$21+ W9*'Best Country'!$E$24+ Y9*'Best Country'!$E$27 )/SUM('Best Country'!$E$5:$E$28), "") | K9: =IFERROR(1-(J9-J$3)/(J$2-J$3), "") | L9: 0.913 | M9: =IFERROR((L9-L$3)/(L$2-L$3), "") -> 0.8989726 | N9: 84.041 | O9: =IFERROR((N9-N$3)/(N$2-N$3), "") -> 0.94670977 | P9: 48671 | Q9: =IFERROR((P9-P$3)/(P$2-P$3), "") -> 0.18567182 | S9: =IFERROR(1-(R9-R$3)/(R$2-R$3), "") | U9: =IFERROR((T9-T$3)/(T$2-T$3), "") | W9: =IFERROR(1-(V9-V$3)/(V$2-V$3), "") | Y9: =IFERROR((X9-X$3)/(X$2-X$3), "")
A10: Oceania | D10: Bangladesh | E10: 52.31 | G10: Africa | H10: Angola | I10: =IFERROR(( K10*'Best Country'!$E$12+ M10*'Best Country'!$E$15+ O10*'Best Country'!$E$18+ Q10*'Best Country'!$E$9+ S10*'Best Country'!$E$6+ U10*'Best Country'!$E$21+ W10*'Best Country'!$E$24+ Y10*'Best Country'!$E$27 )/SUM('Best Country'!$E$5:$E$28), "") | J10: 0.51264286 | K10: =IFERROR(1-(J10-J$3)/(J$2-J$3), "") -> 0.30198722 | L10: 0.616 | M10: =IFERROR((L10-L$3)/(L$2-L$3), "") -> 0.39041096 | N10: 64.617 | O10: =IFERROR((N10-N$3)/(N$2-N$3), "") -> 0.3250224 | P10: 2903 | Q10: =IFERROR((P10-P$3)/(P$2-P$3), "") -> 0.0098898482 | S10: =IFERROR(1-(R10-R$3)/(R$2-R$3), "") | U10: =IFERROR((T10-T$3)/(T$2-T$3), "") | W10: =IFERROR(1-(V10-V$3)/(V$2-V$3), "") | Y10: =IFERROR((X10-X$3)/(X$2-X$3), "")
A11: South America | D11: Belgium | E11: 68.78 | G11: North America | H11: Anguilla | I11: =IFERROR(( K11*'Best Country'!$E$12+ M11*'Best Country'!$E$15+ O11*'Best Country'!$E$18+ Q11*'Best Country'!$E$9+ S11*'Best Country'!$E$6+ U11*'Best Country'!$E$21+ W11*'Best Country'!$E$24+ Y11*'Best Country'!$E$27 )/SUM('Best Country'!$E$5:$E$28), "") | K11: =IFERROR(1-(J11-J$3)/(J$2-J$3), "") | M11: =IFERROR((L11-L$3)/(L$2-L$3), "") | O11: =IFERROR((N11-N$3)/(N$2-N$3), "") | P11: 28228 | Q11: =IFERROR((P11-P$3)/(P$2-P$3), "") -> 0.10715603 | S11: =IFERROR(1-(R11-R$3)/(R$2-R$3), "") | U11: =IFERROR((T11-T$3)/(T$2-T$3), "") | W11: =IFERROR(1-(V11-V$3)/(V$2-V$3), "") | Y11: =IFERROR((X11-X$3)/(X$2-X$3), "")
D12: Bosnia and Herzegovina | E12: 63.45 | G12: North America | H12: Antigua and Barbuda | I12: =IFERROR(( K12*'Best Country'!$E$12+ M12*'Best Country'!$E$15+ O12*'Best Country'!$E$18+ Q12*'Best Country'!$E$9+ S12*'Best Country'!$E$6+ U12*'Best Country'!$E$21+ W12*'Best Country'!$E$24+ Y12*'Best Country'!$E$27 )/SUM('Best Country'!$E$5:$E$28), "") | K12: =IFERROR(1-(J12-J$3)/(J$2-J$3), "") | L12: 0.851 | M12: =IFERROR((L12-L$3)/(L$2-L$3), "") -> 0.79280822 | N12: 77.598 | O12: =IFERROR((N12-N$3)/(N$2-N$3), "") -> 0.74049417 | P12: 25189 | Q12: =IFERROR((P12-P$3)/(P$2-P$3), "") -> 0.095484084 | S12: =IFERROR(1-(R12-R$3)/(R$2-R$3), "") | U12: =IFERROR((T12-T$3)/(T$2-T$3), "") | W12: =IFERROR(1-(V12-V$3)/(V$2-V$3), "") | Y12: =IFERROR((X12-X$3)/(X$2-X$3), "")
D13: Brazil | E13: 55.29 | G13: South America | H13: Argentina | I13: =IFERROR(( K13*'Best Country'!$E$12+ M13*'Best Country'!$E$15+ O13*'Best Country'!$E$18+ Q13*'Best Country'!$E$9+ S13*'Best Country'!$E$6+ U13*'Best Country'!$E$21+ W13*'Best Country'!$E$24+ Y13*'Best Country'!$E$27 )/SUM('Best Country'!$E$5:$E$28), "") -> 0.58519334 | J13: 0.42390975 | K13: =IFERROR(1-(J13-J$3)/(J$2-J$3), "") -> 0.52981883 | L13: 0.865 | M13: =IFERROR((L13-L$3)/(L$2-L$3), "") -> 0.81678082 | N13: 77.395 | O13: =IFERROR((N13-N$3)/(N$2-N$3), "") -> 0.73399693 | P13: 14908 | Q13: =IFERROR((P13-P$3)/(P$2-P$3), "") -> 0.055997665 | R13: 26.6 | S13: =IFERROR(1-(R13-R$3)/(R$2-R$3), "") -> 0.81566265 | T13: 36.7 | U13: =IFERROR((T13-T$3)/(T$2-T$3), "") -> 0.26179604 | V13: 67.9 | W13: =IFERROR(1-(V13-V$3)/(V$2-V$3), "") -> 0.40295359 | X13: 6.397 | Y13: =IFERROR((X13-X$3)/(X$2-X$3), "") -> 0.7898619
A14: Top Country | B14: Top Rating | D14: Bulgaria | E14: 60.84 | G14: Asia | H14: Armenia | I14: =IFERROR(( K14*'Best Country'!$E$12+ M14*'Best Country'!$E$15+ O14*'Best Country'!$E$18+ Q14*'Best Country'!$E$9+ S14*'Best Country'!$E$6+ U14*'Best Country'!$E$21+ W14*'Best Country'!$E$24+ Y14*'Best Country'!$E$27 )/SUM('Best Country'!$E$5:$E$28), "") -> 0.6335177 | J14: 0.2715465 | K14: =IFERROR(1-(J14-J$3)/(J$2-J$3), "") -> 0.92102754 | L14: 0.811 | M14: =IFERROR((L14-L$3)/(L$2-L$3), "") -> 0.72431507 | N14: 75.683 | O14: =IFERROR((N14-N$3)/(N$2-N$3), "") -> 0.67920241 | P14: 8894 | Q14: =IFERROR((P14-P$3)/(P$2-P$3), "") -> 0.032899588 | R14: 29.7 | S14: =IFERROR(1-(R14-R$3)/(R$2-R$3), "") -> 0.77831325 | T14: 77.6 | U14: =IFERROR((T14-T$3)/(T$2-T$3), "") -> 0.88432268 | V14: 60 | W14: =IFERROR(1-(V14-V$3)/(V$2-V$3), "") -> 0.56962025 | X14: 5.494 | Y14: =IFERROR((X14-X$3)/(X$2-X$3), "") -> 0.64814815
A15: {=_xlfn.XLOOKUP(B15,_xlfn.ANCHORARRAY( B37),_xlfn.ANCHORARRAY( A37))} -> Finland | B15: =MAX(_xlfn.ANCHORARRAY(B37)) -> 73.26 | D15: Canada | E15: 68.29 | G15: North America | H15: Aruba | I15: =IFERROR(( K15*'Best Country'!$E$12+ M15*'Best Country'!$E$15+ O15*'Best Country'!$E$18+ Q15*'Best Country'!$E$9+ S15*'Best Country'!$E$6+ U15*'Best Country'!$E$21+ W15*'Best Country'!$E$24+ Y15*'Best Country'!$E$27 )/SUM('Best Country'!$E$5:$E$28), "") | K15: =IFERROR(1-(J15-J$3)/(J$2-J$3), "") | M15: =IFERROR((L15-L$3)/(L$2-L$3), "") | O15: =IFERROR((N15-N$3)/(N$2-N$3), "") | P15: 37911 | Q15: =IFERROR((P15-P$3)/(P$2-P$3), "") -> 0.1443457 | S15: =IFERROR(1-(R15-R$3)/(R$2-R$3), "") | U15: =IFERROR((T15-T$3)/(T$2-T$3), "") | W15: =IFERROR(1-(V15-V$3)/(V$2-V$3), "") | Y15: =IFERROR((X15-X$3)/(X$2-X$3), "")
D16: Chile | E16: 61.19 | G16: Oceania | H16: Australia | I16: =IFERROR(( K16*'Best Country'!$E$12+ M16*'Best Country'!$E$15+ O16*'Best Country'!$E$18+ Q16*'Best Country'!$E$9+ S16*'Best Country'!$E$6+ U16*'Best Country'!$E$21+ W16*'Best Country'!$E$24+ Y16*'Best Country'!$E$27 )/SUM('Best Country'!$E$5:$E$28), "") -> 0.68129345 | J16: 0.34332526 | K16: =IFERROR(1-(J16-J$3)/(J$2-J$3), "") -> 0.73672801 | L16: 0.958 | M16: =IFERROR((L16-L$3)/(L$2-L$3), "") -> 0.9760274 | N16: 83.923 | O16: =IFERROR((N16-N$3)/(N$2-N$3), "") -> 0.94293304 | P16: 65681 | Q16: =IFERROR((P16-P$3)/(P$2-P$3), "") -> 0.25100243 | R16: 49.5 | S16: =IFERROR(1-(R16-R$3)/(R$2-R$3), "") -> 0.53975904 | T16: 52.6 | U16: =IFERROR((T16-T$3)/(T$2-T$3), "") -> 0.50380518 | V16: 73.1 | W16: =IFERROR(1-(V16-V$3)/(V$2-V$3), "") -> 0.29324895 | X16: 6.974 | Y16: =IFERROR((X16-X$3)/(X$2-X$3), "") -> 0.88041431
D17: China | E17: 62.92 | G17: Europe | H17: Austria | I17: =IFERROR(( K17*'Best Country'!$E$12+ M17*'Best Country'!$E$15+ O17*'Best Country'!$E$18+ Q17*'Best Country'!$E$9+ S17*'Best Country'!$E$6+ U17*'Best Country'!$E$21+ W17*'Best Country'!$E$24+ Y17*'Best Country'!$E$27 )/SUM('Best Country'!$E$5:$E$28), "") -> 0.68495204 | J17: 0.3089293 | K17: =IFERROR(1-(J17-J$3)/(J$2-J$3), "") -> 0.82504326 | L17: 0.93 | M17: =IFERROR((L17-L$3)/(L$2-L$3), "") -> 0.92808219 | N17: 81.956 | O17: =IFERROR((N17-N$3)/(N$2-N$3), "") -> 0.87997696 | P17: 58627 | Q17: =IFERROR((P17-P$3)/(P$2-P$3), "") -> 0.22391 | R17: 49.1 | S17: =IFERROR(1-(R17-R$3)/(R$2-R$3), "") -> 0.54457831 | T17: 71.7 | U17: =IFERROR((T17-T$3)/(T$2-T$3), "") -> 0.79452055 | V17: 78.5 | W17: =IFERROR(1-(V17-V$3)/(V$2-V$3), "") -> 0.17932489 | X17: 6.81 | Y17: =IFERROR((X17-X$3)/(X$2-X$3), "") -> 0.85467671
A18: Top 10 sorted | D18: Colombia | E18: 52.87 | G18: Asia | H18: Azerbaijan | I18: =IFERROR(( K18*'Best Country'!$E$12+ M18*'Best Country'!$E$15+ O18*'Best Country'!$E$18+ Q18*'Best Country'!$E$9+ S18*'Best Country'!$E$6+ U18*'Best Country'!$E$21+ W18*'Best Country'!$E$24+ Y18*'Best Country'!$E$27 )/SUM('Best Country'!$E$5:$E$28), "") | K18: =IFERROR(1-(J18-J$3)/(J$2-J$3), "") | L18: 0.789 | M18: =IFERROR((L18-L$3)/(L$2-L$3), "") -> 0.68664384 | N18: 74.429 | O18: =IFERROR((N18-N$3)/(N$2-N$3), "") -> 0.6390667 | P18: 7585 | Q18: =IFERROR((P18-P$3)/(P$2-P$3), "") -> 0.027872089 | R18: 20.7 | S18: =IFERROR(1-(R18-R$3)/(R$2-R$3), "") -> 0.88674699 | T18: 68.2 | U18: =IFERROR((T18-T$3)/(T$2-T$3), "") -> 0.7412481 | V18: 49.1 | W18: =IFERROR(1-(V18-V$3)/(V$2-V$3), "") -> 0.79957806 | X18: 4.875 | Y18: =IFERROR((X18-X$3)/(X$2-X$3), "") -> 0.55100439
A19: Country | B19: Rating | D19: Costa Rica | E19: 60.81 | G19: North America | H19: Bahamas | I19: =IFERROR(( K19*'Best Country'!$E$12+ M19*'Best Country'!$E$15+ O19*'Best Country'!$E$18+ Q19*'Best Country'!$E$9+ S19*'Best Country'!$E$6+ U19*'Best Country'!$E$21+ W19*'Best Country'!$E$24+ Y19*'Best Country'!$E$27 )/SUM('Best Country'!$E$5:$E$28), "") | K19: =IFERROR(1-(J19-J$3)/(J$2-J$3), "") | L19: 0.82 | M19: =IFERROR((L19-L$3)/(L$2-L$3), "") -> 0.73972603 | N19: 74.552 | O19: =IFERROR((N19-N$3)/(N$2-N$3), "") -> 0.64300346 | P19: 37659 | Q19: =IFERROR((P19-P$3)/(P$2-P$3), "") -> 0.14337783 | R19: 68.7 | S19: =IFERROR(1-(R19-R$3)/(R$2-R$3), "") -> 0.30843373 | U19: =IFERROR((T19-T$3)/(T$2-T$3), "") | W19: =IFERROR(1-(V19-V$3)/(V$2-V$3), "") | Y19: =IFERROR((X19-X$3)/(X$2-X$3), "")
A20: {=_xlfn.XLOOKUP(_xlfn.ANCHORARRAY(B20),_xlfn.ANCHORARRAY( B37),_xlfn.ANCHORARRAY( A37))} -> Poland | B20: {=_xlfn.TAKE(_xlfn._xlws.SORT(_xlfn.ANCHORARRAY(B37), 1, 1), -10)} -> 70.16 | D20: Croatia | E20: 66.07 | G20: Asia | H20: Bahrain | I20: =IFERROR(( K20*'Best Country'!$E$12+ M20*'Best Country'!$E$15+ O20*'Best Country'!$E$18+ Q20*'Best Country'!$E$9+ S20*'Best Country'!$E$6+ U20*'Best Country'!$E$21+ W20*'Best Country'!$E$24+ Y20*'Best Country'!$E$27 )/SUM('Best Country'!$E$5:$E$28), "") | K20: =IFERROR(1-(J20-J$3)/(J$2-J$3), "") | L20: 0.899 | M20: =IFERROR((L20-L$3)/(L$2-L$3), "") -> 0.875 | N20: 81.284 | O20: =IFERROR((N20-N$3)/(N$2-N$3), "") -> 0.85846883 | P20: 29105 | Q20: =IFERROR((P20-P$3)/(P$2-P$3), "") -> 0.11052433 | R20: 35.2 | S20: =IFERROR(1-(R20-R$3)/(R$2-R$3), "") -> 0.71204819 | U20: =IFERROR((T20-T$3)/(T$2-T$3), "") | W20: =IFERROR(1-(V20-V$3)/(V$2-V$3), "") | X20: 6.03 | Y20: =IFERROR((X20-X$3)/(X$2-X$3), "") -> 0.73226616
A21: Sweden | B21: 70.59 | D21: Cyprus | E21: 66.74 | G21: Asia | H21: Bangladesh | I21: =IFERROR(( K21*'Best Country'!$E$12+ M21*'Best Country'!$E$15+ O21*'Best Country'!$E$18+ Q21*'Best Country'!$E$9+ S21*'Best Country'!$E$6+ U21*'Best Country'!$E$21+ W21*'Best Country'!$E$24+ Y21*'Best Country'!$E$27 )/SUM('Best Country'!$E$5:$E$28), "") -> 0.52310361 | J21: 0.33373156 | K21: =IFERROR(1-(J21-J$3)/(J$2-J$3), "") -> 0.76136085 | L21: 0.685 | M21: =IFERROR((L21-L$3)/(L$2-L$3), "") -> 0.50856164 | N21: 74.672 | O21: =IFERROR((N21-N$3)/(N$2-N$3), "") -> 0.64684419 | P21: 2659 | Q21: =IFERROR((P21-P$3)/(P$2-P$3), "") -> 0.0089527131 | R21: 13 | S21: =IFERROR(1-(R21-R$3)/(R$2-R$3), "") -> 0.97951807 | T21: 38.5 | U21: =IFERROR((T21-T$3)/(T$2-T$3), "") -> 0.2891933 | V21: 41.7 | W21: =IFERROR(1-(V21-V$3)/(V$2-V$3), "") -> 0.9556962 | X21: 3.851 | Y21: =IFERROR((X21-X$3)/(X$2-X$3), "") -> 0.39030132
A22: Luxembourg | B22: 70.86 | D22: Czech Republic | E22: 69.85 | G22: North America | H22: Barbados | I22: =IFERROR(( K22*'Best Country'!$E$12+ M22*'Best Country'!$E$15+ O22*'Best Country'!$E$18+ Q22*'Best Country'!$E$9+ S22*'Best Country'!$E$6+ U22*'Best Country'!$E$21+ W22*'Best Country'!$E$24+ Y22*'Best Country'!$E$27 )/SUM('Best Country'!$E$5:$E$28), "") | J22: 0.34068036 | K22: =IFERROR(1-(J22-J$3)/(J$2-J$3), "") -> 0.74351907 | L22: 0.811 | M22: =IFERROR((L22-L$3)/(L$2-L$3), "") -> 0.72431507 | N22: 76.178 | O22: =IFERROR((N22-N$3)/(N$2-N$3), "") -> 0.69504545 | P22: 26721 | Q22: =IFERROR((P22-P$3)/(P$2-P$3), "") -> 0.10136806 | S22: =IFERROR(1-(R22-R$3)/(R$2-R$3), "") | U22: =IFERROR((T22-T$3)/(T$2-T$3), "") | W22: =IFERROR(1-(V22-V$3)/(V$2-V$3), "") | Y22: =IFERROR((X22-X$3)/(X$2-X$3), "")
A23: Netherlands | B23: 71.98 | D23: Denmark | E23: 72.46 | G23: Europe | H23: Belarus | I23: =IFERROR(( K23*'Best Country'!$E$12+ M23*'Best Country'!$E$15+ O23*'Best Country'!$E$18+ Q23*'Best Country'!$E$9+ S23*'Best Country'!$E$6+ U23*'Best Country'!$E$21+ W23*'Best Country'!$E$24+ Y23*'Best Country'!$E$27 )/SUM('Best Country'!$E$5:$E$28), "") | J23: 0.24383356 | K23: =IFERROR(1-(J23-J$3)/(J$2-J$3), "") -> 0.99218344 | L23: 0.824 | M23: =IFERROR((L23-L$3)/(L$2-L$3), "") -> 0.74657534 | N23: 74.434 | O23: =IFERROR((N23-N$3)/(N$2-N$3), "") -> 0.63922673 | P23: 7953 | Q23: =IFERROR((P23-P$3)/(P$2-P$3), "") -> 0.029285473 | R23: 18.4 | S23: =IFERROR(1-(R23-R$3)/(R$2-R$3), "") -> 0.91445783 | T23: 50.9 | U23: =IFERROR((T23-T$3)/(T$2-T$3), "") -> 0.47792998 | V23: 49.3 | W23: =IFERROR(1-(V23-V$3)/(V$2-V$3), "") -> 0.79535865 | Y23: =IFERROR((X23-X$3)/(X$2-X$3), "")
A24: Denmark | B24: 72.46 | D24: Ecuador | E24: 53.33 | G24: Europe | H24: Belgium | I24: =IFERROR(( K24*'Best Country'!$E$12+ M24*'Best Country'!$E$15+ O24*'Best Country'!$E$18+ Q24*'Best Country'!$E$9+ S24*'Best Country'!$E$6+ U24*'Best Country'!$E$21+ W24*'Best Country'!$E$24+ Y24*'Best Country'!$E$27 )/SUM('Best Country'!$E$5:$E$28), "") -> 0.68783501 | J24: 0.26375556 | K24: =IFERROR(1-(J24-J$3)/(J$2-J$3), "") -> 0.9410316 | L24: 0.951 | M24: =IFERROR((L24-L$3)/(L$2-L$3), "") -> 0.9640411 | N24: 82.115 | O24: =IFERROR((N24-N$3)/(N$2-N$3), "") -> 0.88506593 | P24: 58244 | Q24: =IFERROR((P24-P$3)/(P$2-P$3), "") -> 0.22243901 | R24: 45.9 | S24: =IFERROR(1-(R24-R$3)/(R$2-R$3), "") -> 0.58313253 | T24: 50.5 | U24: =IFERROR((T24-T$3)/(T$2-T$3), "") -> 0.4718417 | V24: 75.8 | W24: =IFERROR(1-(V24-V$3)/(V$2-V$3), "") -> 0.23628692 | X24: 6.91 | Y24: =IFERROR((X24-X$3)/(X$2-X$3), "") -> 0.87037037
A25: Ireland | B25: 72.6 | D25: Egypt | E25: 55.68 | G25: North America | H25: Belize | I25: =IFERROR(( K25*'Best Country'!$E$12+ M25*'Best Country'!$E$15+ O25*'Best Country'!$E$18+ Q25*'Best Country'!$E$9+ S25*'Best Country'!$E$6+ U25*'Best Country'!$E$21+ W25*'Best Country'!$E$24+ Y25*'Best Country'!$E$27 )/SUM('Best Country'!$E$5:$E$28), "") | J25: 0.39949584 | K25: =IFERROR(1-(J25-J$3)/(J$2-J$3), "") -> 0.59250412 | L25: 0.721 | M25: =IFERROR((L25-L$3)/(L$2-L$3), "") -> 0.57020548 | N25: 73.566 | O25: =IFERROR((N25-N$3)/(N$2-N$3), "") -> 0.6114454 | P25: 8538 | Q25: =IFERROR((P25-P$3)/(P$2-P$3), "") -> 0.031532293 | R25: 28.3 | S25: =IFERROR(1-(R25-R$3)/(R$2-R$3), "") -> 0.79518072 | U25: =IFERROR((T25-T$3)/(T$2-T$3), "") | W25: =IFERROR(1-(V25-V$3)/(V$2-V$3), "") | X25: 6.711 | Y25: =IFERROR((X25-X$3)/(X$2-X$3), "") -> 0.83913999
A26: Iceland | B26: 72.73 | D26: Estonia | E26: 66.57 | G26: Africa | H26: Benin | I26: =IFERROR(( K26*'Best Country'!$E$12+ M26*'Best Country'!$E$15+ O26*'Best Country'!$E$18+ Q26*'Best Country'!$E$9+ S26*'Best Country'!$E$6+ U26*'Best Country'!$E$21+ W26*'Best Country'!$E$24+ Y26*'Best Country'!$E$27 )/SUM('Best Country'!$E$5:$E$28), "") | J26: 0.34395808 | K26: =IFERROR(1-(J26-J$3)/(J$2-J$3), "") -> 0.73510318 | L26: 0.515 | M26: =IFERROR((L26-L$3)/(L$2-L$3), "") -> 0.21746575 | N26: 60.774 | O26: =IFERROR((N26-N$3)/(N$2-N$3), "") -> 0.20202279 | P26: 1501 | Q26: =IFERROR((P26-P$3)/(P$2-P$3), "") -> 0.0045051619 | S26: =IFERROR(1-(R26-R$3)/(R$2-R$3), "") | U26: =IFERROR((T26-T$3)/(T$2-T$3), "") | W26: =IFERROR(1-(V26-V$3)/(V$2-V$3), "") | X26: 4.357 | Y26: =IFERROR((X26-X$3)/(X$2-X$3), "") -> 0.46971124
A27: Slovenia | B27: 72.75 | D27: Finland | E27: 73.26 | G27: North America | H27: Bermuda | I27: =IFERROR(( K27*'Best Country'!$E$12+ M27*'Best Country'!$E$15+ O27*'Best Country'!$E$18+ Q27*'Best Country'!$E$9+ S27*'Best Country'!$E$6+ U27*'Best Country'!$E$21+ W27*'Best Country'!$E$24+ Y27*'Best Country'!$E$27 )/SUM('Best Country'!$E$5:$E$28), "") | K27: =IFERROR(1-(J27-J$3)/(J$2-J$3), "") | M27: =IFERROR((L27-L$3)/(L$2-L$3), "") | O27: =IFERROR((N27-N$3)/(N$2-N$3), "") | P27: 126120 | Q27: =IFERROR((P27-P$3)/(P$2-P$3), "") -> 0.48313157 | S27: =IFERROR(1-(R27-R$3)/(R$2-R$3), "") | U27: =IFERROR((T27-T$3)/(T$2-T$3), "") | W27: =IFERROR(1-(V27-V$3)/(V$2-V$3), "") | Y27: =IFERROR((X27-X$3)/(X$2-X$3), "")
A28: Norway | B28: 72.93 | D28: France | E28: 64.44 | G28: Asia | H28: Bhutan | I28: =IFERROR(( K28*'Best Country'!$E$12+ M28*'Best Country'!$E$15+ O28*'Best Country'!$E$18+ Q28*'Best Country'!$E$9+ S28*'Best Country'!$E$6+ U28*'Best Country'!$E$21+ W28*'Best Country'!$E$24+ Y28*'Best Country'!$E$27 )/SUM('Best Country'!$E$5:$E$28), "") | J28: 0.2845992 | K28: =IFERROR(1-(J28-J$3)/(J$2-J$3), "") -> 0.88751336 | L28: 0.698 | M28: =IFERROR((L28-L$3)/(L$2-L$3), "") -> 0.53082192 | N28: 72.975 | O28: =IFERROR((N28-N$3)/(N$2-N$3), "") -> 0.59252977 | P28: 4295 | Q28: =IFERROR((P28-P$3)/(P$2-P$3), "") -> 0.015236127 | S28: =IFERROR(1-(R28-R$3)/(R$2-R$3), "") | U28: =IFERROR((T28-T$3)/(T$2-T$3), "") | W28: =IFERROR(1-(V28-V$3)/(V$2-V$3), "") | Y28: =IFERROR((X28-X$3)/(X$2-X$3), "")
A29: Finland | B29: 73.26 | D29: Georgia | E29: 62.59 | G29: South America | H29: Bolivia | I29: =IFERROR(( K29*'Best Country'!$E$12+ M29*'Best Country'!$E$15+ O29*'Best Country'!$E$18+ Q29*'Best Country'!$E$9+ S29*'Best Country'!$E$6+ U29*'Best Country'!$E$21+ W29*'Best Country'!$E$24+ Y29*'Best Country'!$E$27 )/SUM('Best Country'!$E$5:$E$28), "") | J29: 0.42050114 | K29: =IFERROR(1-(J29-J$3)/(J$2-J$3), "") -> 0.5385708 | L29: 0.733 | M29: =IFERROR((L29-L$3)/(L$2-L$3), "") -> 0.59075342 | N29: 68.581 | O29: =IFERROR((N29-N$3)/(N$2-N$3), "") -> 0.45189476 | P29: 4478 | Q29: =IFERROR((P29-P$3)/(P$2-P$3), "") -> 0.015938979 | R29: 18.1 | S29: =IFERROR(1-(R29-R$3)/(R$2-R$3), "") -> 0.91807229 | U29: =IFERROR((T29-T$3)/(T$2-T$3), "") | W29: =IFERROR(1-(V29-V$3)/(V$2-V$3), "") | X29: 5.868 | Y29: =IFERROR((X29-X$3)/(X$2-X$3), "") -> 0.70684244
D30: Germany | E30: 68.11 | G30: Europe | H30: Bosnia and Herzegovina | I30: =IFERROR(( K30*'Best Country'!$E$12+ M30*'Best Country'!$E$15+ O30*'Best Country'!$E$18+ Q30*'Best Country'!$E$9+ S30*'Best Country'!$E$6+ U30*'Best Country'!$E$21+ W30*'Best Country'!$E$24+ Y30*'Best Country'!$E$27 )/SUM('Best Country'!$E$5:$E$28), "") -> 0.63446473 | J30: 0.33030185 | K30: =IFERROR(1-(J30-J$3)/(J$2-J$3), "") -> 0.77016699 | L30: 0.804 | M30: =IFERROR((L30-L$3)/(L$2-L$3), "") -> 0.71232877 | N30: 77.85 | O30: =IFERROR((N30-N$3)/(N$2-N$3), "") -> 0.74855972 | P30: 9174 | Q30: =IFERROR((P30-P$3)/(P$2-P$3), "") -> 0.033974989 | R30: 23.4 | S30: =IFERROR(1-(R30-R$3)/(R$2-R$3), "") -> 0.85421687 | T30: 58.8 | U30: =IFERROR((T30-T$3)/(T$2-T$3), "") -> 0.59817352 | V30: 54.9 | W30: =IFERROR(1-(V30-V$3)/(V$2-V$3), "") -> 0.67721519 | X30: 6.136 | Y30: =IFERROR((X30-X$3)/(X$2-X$3), "") -> 0.74890144
D31: Greece | E31: 64.83 | G31: Africa | H31: Botswana | I31: =IFERROR(( K31*'Best Country'!$E$12+ M31*'Best Country'!$E$15+ O31*'Best Country'!$E$18+ Q31*'Best Country'!$E$9+ S31*'Best Country'!$E$6+ U31*'Best Country'!$E$21+ W31*'Best Country'!$E$24+ Y31*'Best Country'!$E$27 )/SUM('Best Country'!$E$5:$E$28), "") | J31: 0.5490736 | K31: =IFERROR(1-(J31-J$3)/(J$2-J$3), "") -> 0.20844745 | L31: 0.731 | M31: =IFERROR((L31-L$3)/(L$2-L$3), "") -> 0.58732877 | N31: 69.163 | O31: =IFERROR((N31-N$3)/(N$2-N$3), "") -> 0.47052234 | P31: 7572 | Q31: =IFERROR((P31-P$3)/(P$2-P$3), "") -> 0.027822159 | R31: 26.2 | S31: =IFERROR(1-(R31-R$3)/(R$2-R$3), "") -> 0.82048193 | U31: =IFERROR((T31-T$3)/(T$2-T$3), "") | W31: =IFERROR(1-(V31-V$3)/(V$2-V$3), "") | X31: 3.438 | Y31: =IFERROR((X31-X$3)/(X$2-X$3), "") -> 0.3254865
D32: Hungary | E32: 66.17 | G32: South America | H32: Brazil | I32: =IFERROR(( K32*'Best Country'!$E$12+ M32*'Best Country'!$E$15+ O32*'Best Country'!$E$18+ Q32*'Best Country'!$E$9+ S32*'Best Country'!$E$6+ U32*'Best Country'!$E$21+ W32*'Best Country'!$E$24+ Y32*'Best Country'!$E$27 )/SUM('Best Country'!$E$5:$E$28), "") -> 0.55290268 | J32: 0.5163944 | K32: =IFERROR(1-(J32-J$3)/(J$2-J$3), "") -> 0.29235474 | L32: 0.786 | M32: =IFERROR((L32-L$3)/(L$2-L$3), "") -> 0.68150685 | N32: 75.848 | O32: =IFERROR((N32-N$3)/(N$2-N$3), "") -> 0.68448342 | P32: 9990 | Q32: =IFERROR((P32-P$3)/(P$2-P$3), "") -> 0.037109015 | R32: 19.7 | S32: =IFERROR(1-(R32-R$3)/(R$2-R$3), "") -> 0.89879518 | T32: 35.8 | U32: =IFERROR((T32-T$3)/(T$2-T$3), "") -> 0.24809741 | V32: 59.2 | W32: =IFERROR(1-(V32-V$3)/(V$2-V$3), "") -> 0.58649789 | X32: 6.494 | Y32: =IFERROR((X32-X$3)/(X$2-X$3), "") -> 0.80508475
A33: Ratings by Continent: | D33: Iceland | E33: 72.73 | G33: North America | H33: British Virgin Islands | I33: =IFERROR(( K33*'Best Country'!$E$12+ M33*'Best Country'!$E$15+ O33*'Best Country'!$E$18+ Q33*'Best Country'!$E$9+ S33*'Best Country'!$E$6+ U33*'Best Country'!$E$21+ W33*'Best Country'!$E$24+ Y33*'Best Country'!$E$27 )/SUM('Best Country'!$E$5:$E$28), "") | K33: =IFERROR(1-(J33-J$3)/(J$2-J$3), "") | M33: =IFERROR((L33-L$3)/(L$2-L$3), "") | O33: =IFERROR((N33-N$3)/(N$2-N$3), "") | P33: 37900 | Q33: =IFERROR((P33-P$3)/(P$2-P$3), "") -> 0.14430345 | S33: =IFERROR(1-(R33-R$3)/(R$2-R$3), "") | U33: =IFERROR((T33-T$3)/(T$2-T$3), "") | W33: =IFERROR(1-(V33-V$3)/(V$2-V$3), "") | Y33: =IFERROR((X33-X$3)/(X$2-X$3), "")
A34: ='Best Country'!H3 -> Europe | D34: India | E34: 54.24 | G34: Asia | H34: Brunei | I34: =IFERROR(( K34*'Best Country'!$E$12+ M34*'Best Country'!$E$15+ O34*'Best Country'!$E$18+ Q34*'Best Country'!$E$9+ S34*'Best Country'!$E$6+ U34*'Best Country'!$E$21+ W34*'Best Country'!$E$24+ Y34*'Best Country'!$E$27 )/SUM('Best Country'!$E$5:$E$28), "") | K34: =IFERROR(1-(J34-J$3)/(J$2-J$3), "") | L34: 0.837 | M34: =IFERROR((L34-L$3)/(L$2-L$3), "") -> 0.76883562 | N34: 75.327 | O34: =IFERROR((N34-N$3)/(N$2-N$3), "") -> 0.66780822 | P34: 34325 | Q34: =IFERROR((P34-P$3)/(P$2-P$3), "") -> 0.13057288 | R34: 33.4 | S34: =IFERROR(1-(R34-R$3)/(R$2-R$3), "") -> 0.73373494 | U34: =IFERROR((T34-T$3)/(T$2-T$3), "") | W34: =IFERROR(1-(V34-V$3)/(V$2-V$3), "") | Y34: =IFERROR((X34-X$3)/(X$2-X$3), "")
A35: Country | B35: Rating | D35: Indonesia | E35: 56.05 | G35: Europe | H35: Bulgaria | I35: =IFERROR(( K35*'Best Country'!$E$12+ M35*'Best Country'!$E$15+ O35*'Best Country'!$E$18+ Q35*'Best Country'!$E$9+ S35*'Best Country'!$E$6+ U35*'Best Country'!$E$21+ W35*'Best Country'!$E$24+ Y35*'Best Country'!$E$27 )/SUM('Best Country'!$E$5:$E$28), "") -> 0.60840415 | J35: 0.38201502 | K35: =IFERROR(1-(J35-J$3)/(J$2-J$3), "") -> 0.63738797 | L35: 0.845 | M35: =IFERROR((L35-L$3)/(L$2-L$3), "") -> 0.78253425 | N35: 75.636 | O35: =IFERROR((N35-N$3)/(N$2-N$3), "") -> 0.67769812 | P35: 17426 | Q35: =IFERROR((P35-P$3)/(P$2-P$3), "") -> 0.065668592 | R35: 27.3 | S35: =IFERROR(1-(R35-R$3)/(R$2-R$3), "") -> 0.80722892 | T35: 64.1 | U35: =IFERROR((T35-T$3)/(T$2-T$3), "") -> 0.67884323 | V35: 58.2 | W35: =IFERROR(1-(V35-V$3)/(V$2-V$3), "") -> 0.60759494 | X35: 5.554 | Y35: =IFERROR((X35-X$3)/(X$2-X$3), "") -> 0.65756434
D36: Iran | E36: 59.21 | G36: Africa | H36: Burkina Faso | I36: =IFERROR(( K36*'Best Country'!$E$12+ M36*'Best Country'!$E$15+ O36*'Best Country'!$E$18+ Q36*'Best Country'!$E$9+ S36*'Best Country'!$E$6+ U36*'Best Country'!$E$21+ W36*'Best Country'!$E$24+ Y36*'Best Country'!$E$27 )/SUM('Best Country'!$E$5:$E$28), "") | J36: 0.37391287 | K36: =IFERROR(1-(J36-J$3)/(J$2-J$3), "") -> 0.6581911 | L36: 0.459 | M36: =IFERROR((L36-L$3)/(L$2-L$3), "") -> 0.12157534 | N36: 61.092 | O36: =IFERROR((N36-N$3)/(N$2-N$3), "") -> 0.21220074 | P36: 1124 | Q36: =IFERROR((P36-P$3)/(P$2-P$3), "") -> 0.0030572113 | S36: =IFERROR(1-(R36-R$3)/(R$2-R$3), "") | U36: =IFERROR((T36-T$3)/(T$2-T$3), "") | W36: =IFERROR(1-(V36-V$3)/(V$2-V$3), "") | X36: 4.383 | Y36: =IFERROR((X36-X$3)/(X$2-X$3), "") -> 0.47379159
A37: {=_xlfn._xlws.FILTER(_xlfn.ANCHORARRAY(H5), ((A34="World") + (A34=_xlfn.ANCHORARRAY(G5))) * (I5:I238<>""))} -> Albania | B37: {=ROUND(_xlfn._xlws.FILTER(I5:I238*100, ((A34="World") + (A34=_xlfn.ANCHORARRAY(G5))) * (I5:I238<>"")), B1)} -> 62.38 | D37: Ireland | E37: 72.6 | G37: Africa | H37: Burundi | I37: =IFERROR(( K37*'Best Country'!$E$12+ M37*'Best Country'!$E$15+ O37*'Best Country'!$E$18+ Q37*'Best Country'!$E$9+ S37*'Best Country'!$E$6+ U37*'Best Country'!$E$21+ W37*'Best Country'!$E$24+ Y37*'Best Country'!$E$27 )/SUM('Best Country'!$E$5:$E$28), "") | J37: 0.37456086 | K37: =IFERROR(1-(J37-J$3)/(J$2-J$3), "") -> 0.65652731 | L37: 0.439 | M37: =IFERROR((L37-L$3)/(L$2-L$3), "") -> 0.087328767 | N37: 63.651 | O37: =IFERROR((N37-N$3)/(N$2-N$3), "") -> 0.29410447 | P37: 469 | Q37: =IFERROR((P37-P$3)/(P$2-P$3), "") -> 0.0005415412 | S37: =IFERROR(1-(R37-R$3)/(R$2-R$3), "") | U37: =IFERROR((T37-T$3)/(T$2-T$3), "") | W37: =IFERROR(1-(V37-V$3)/(V$2-V$3), "") | Y37: =IFERROR((X37-X$3)/(X$2-X$3), "")
A38: Austria | B38: 68.5 | D38: Israel | E38: 67.67 | G38: Asia | H38: Cambodia | I38: =IFERROR(( K38*'Best Country'!$E$12+ M38*'Best Country'!$E$15+ O38*'Best Country'!$E$18+ Q38*'Best Country'!$E$9+ S38*'Best Country'!$E$6+ U38*'Best Country'!$E$21+ W38*'Best Country'!$E$24+ Y38*'Best Country'!$E$27 )/SUM('Best Country'!$E$5:$E$28), "") | K38: =IFERROR(1-(J38-J$3)/(J$2-J$3), "") | L38: 0.606 | M38: =IFERROR((L38-L$3)/(L$2-L$3), "") -> 0.37328767 | N38: 70.668 | O38: =IFERROR((N38-N$3)/(N$2-N$3), "") -> 0.51869159 | P38: 2790 | Q38: =IFERROR((P38-P$3)/(P$2-P$3), "") -> 0.0094558471 | R38: 22.6 | S38: =IFERROR(1-(R38-R$3)/(R$2-R$3), "") -> 0.86385542 | U38: =IFERROR((T38-T$3)/(T$2-T$3), "") | W38: =IFERROR(1-(V38-V$3)/(V$2-V$3), "") | X38: 4.341 | Y38: =IFERROR((X38-X$3)/(X$2-X$3), "") -> 0.46720025
A39: Belgium | B39: 68.78 | D39: Italy | E39: 66.32 | G39: Africa | H39: Cameroon | I39: =IFERROR(( K39*'Best Country'!$E$12+ M39*'Best Country'!$E$15+ O39*'Best Country'!$E$18+ Q39*'Best Country'!$E$9+ S39*'Best Country'!$E$6+ U39*'Best Country'!$E$21+ W39*'Best Country'!$E$24+ Y39*'Best Country'!$E$27 )/SUM('Best Country'!$E$5:$E$28), "") | J39: 0.42176074 | K39: =IFERROR(1-(J39-J$3)/(J$2-J$3), "") -> 0.53533664 | L39: 0.588 | M39: =IFERROR((L39-L$3)/(L$2-L$3), "") -> 0.34246575 | N39: 63.7 | O39: =IFERROR((N39-N$3)/(N$2-N$3), "") -> 0.29567277 | P39: 1875 | Q39: =IFERROR((P39-P$3)/(P$2-P$3), "") -> 0.0059415904 | R39: 30.5 | S39: =IFERROR(1-(R39-R$3)/(R$2-R$3), "") -> 0.7686747 | U39: =IFERROR((T39-T$3)/(T$2-T$3), "") | W39: =IFERROR(1-(V39-V$3)/(V$2-V$3), "") | X39: 4.887 | Y39: =IFERROR((X39-X$3)/(X$2-X$3), "") -> 0.55288763
A40: Bosnia and Herzegovina | B40: 63.45 | D40: Japan | E40: 68.26 | G40: North America | H40: Canada | I40: =IFERROR(( K40*'Best Country'!$E$12+ M40*'Best Country'!$E$15+ O40*'Best Country'!$E$18+ Q40*'Best Country'!$E$9+ S40*'Best Country'!$E$6+ U40*'Best Country'!$E$21+ W40*'Best Country'!$E$24+ Y40*'Best Country'!$E$27 )/SUM('Best Country'!$E$5:$E$28), "") -> 0.68289163 | J40: 0.29851684 | K40: =IFERROR(1-(J40-J$3)/(J$2-J$3), "") -> 0.85177835 | L40: 0.939 | M40: =IFERROR((L40-L$3)/(L$2-L$3), "") -> 0.94349315 | N40: 82.63 | O40: =IFERROR((N40-N$3)/(N$2-N$3), "") -> 0.9015491 | P40: 55458 | Q40: =IFERROR((P40-P$3)/(P$2-P$3), "") -> 0.21173877 | R40: 48.1 | S40: =IFERROR(1-(R40-R$3)/(R$2-R$3), "") -> 0.55662651 | T40: 54.2 | U40: =IFERROR((T40-T$3)/(T$2-T$3), "") -> 0.5281583 | V40: 68.6 | W40: =IFERROR(1-(V40-V$3)/(V$2-V$3), "") -> 0.38818565 | X40: 6.803 | Y40: =IFERROR((X40-X$3)/(X$2-X$3), "") -> 0.85357815
A41: Bulgaria | B41: 60.84 | D41: Jordan | E41: 54.7 | G41: Africa | H41: Cape Verde | I41: =IFERROR(( K41*'Best Country'!$E$12+ M41*'Best Country'!$E$15+ O41*'Best Country'!$E$18+ Q41*'Best Country'!$E$9+ S41*'Best Country'!$E$6+ U41*'Best Country'!$E$21+ W41*'Best Country'!$E$24+ Y41*'Best Country'!$E$27 )/SUM('Best Country'!$E$5:$E$28), "") | J41: 0.42381087 | K41: =IFERROR(1-(J41-J$3)/(J$2-J$3), "") -> 0.53007272 | L41: 0.668 | M41: =IFERROR((L41-L$3)/(L$2-L$3), "") -> 0.47945205 | N41: 76.059 | O41: =IFERROR((N41-N$3)/(N$2-N$3), "") -> 0.69123672 | P41: 5283 | Q41: =IFERROR((P41-P$3)/(P$2-P$3), "") -> 0.019030756 | S41: =IFERROR(1-(R41-R$3)/(R$2-R$3), "") | U41: =IFERROR((T41-T$3)/(T$2-T$3), "") | W41: =IFERROR(1-(V41-V$3)/(V$2-V$3), "") | Y41: =IFERROR((X41-X$3)/(X$2-X$3), "")
...

Sheet Best Country (diagrams)

Sheet Correlations

Sheet Correlations (help)

Sheet Data
A1: Alpha-2-Code | B1: Alpha-3-Code | C1: Country | D1: Continent | E1: UN-Member? | F1: Currency | G1: Population | H1: Big Mac Index (% under-/overvalued; raw index) | I1: Big Mac Index (% under-/overvalued; GDP-adjusted) | J1: GDP (IMF '25; USD) | K1: GDP (UN '23; USD) | L1: GDP per capita (USD) | M1: Year of Gini-survey | N1: Gini-Coefficient (2021 prices; income or consumption consolid) | O1: HDI (2023) | P1: Years of life expectancy at birth (2023) | Q1: Expected years of schooling (2023) | R1: Mean years of schooling (2023) | S1: GNI per capita (USD) | T1: Cost of Living Index | U1: Rent Index | V1: Cost of Living Plus Rent Index | W1: Groceries Index | X1: Restaurant Price Index | Y1: Local Purchasing Power Index | Z1: Price To Income Ratio | AA1: Gross Rental Yield City Centre | AB1: Gross Rental Yield Outside of Centre | AC1: Price To Rent Ratio City Centre | AD1: Price To Rent Ratio Outside Of City Centre | AE1: Mortgage As A Percentage Of Income | AF1: Affordability Index | AG1: Quality of Life Index | AH1: Purchasing Power Index | AI1: Safety Index | AJ1: Health Care Index | AK1: Property Price to Income Ratio | AL1: Traffic Commute Time Index | AM1: Pollution Index | AN1: Climate Index | AO1: Word Happieness Report (life evaluation; 3-year-average)
A2: AF | C2: Afghanistan | D2: Asia | E2: TRUE | G2: 43844100 | K2: 16420000000 | L2: 374 | O2: 0.496 | P2: 66.035 | Q2: 10.790143 | R2: 2.5147901 | S2: 1971.5495 | T2: 19.1 | U2: 2 | V2: 11.6 | W2: 16.6 | X2: 13.2 | Y2: 35.7 | AO2: 1.364
A3: AL | B3: ALB | C3: Albania | D3: Europe | E3: TRUE | G3: 2771510 | J3: 28370000000 | K3: 22980000000 | L3: 10237 | M3: 2020 | N3: 0.2941963 | O3: 0.81 | P3: 79.602 | Q3: 14.51015 | R3: 10.175311 | S3: 17627.394 | T3: 43.7 | U3: 15.3 | V3: 31.3 | W3: 44.1 | X3: 40.7 | Y3: 45.1 | Z3: 16.3 | AA3: 4.9 | AB3: 5.7 | AC3: 20.3 | AD3: 17.4 | AE3: 135.1 | AF3: 0.7 | AG3: 104.1 | AH3: 46.3 | AI3: 55.8 | AJ3: 48.2 | AK3: 16.3 | AL3: 36.3 | AM3: 77.3 | AN3: 86.3 | AO3: 5.411
A4: DZ | B4: DZA | C4: Algeria | D4: Africa | E4: TRUE | G4: 47435300 | J4: 268880000000 | K4: 247630000000 | L4: 5668 | M4: 2011 | N4: 0.27615732 | O4: 0.763 | P4: 76.261 | Q4: 15.49516 | R4: 7.416387 | S4: 15114.172 | T4: 26.8 | U4: 3.8 | V4: 16.7 | W4: 36 | X4: 15.4 | Y4: 38.3 | Z4: 16.5 | AA4: 2.8 | AB4: 3 | AC4: 35.2 | AD4: 33.4 | AE4: 143.1 | AF4: 0.7 | AO4: 5.571
A5: AS | C5: American Samoa | D5: Oceania | E5: FALSE
A6: AD | C6: Andorra | D6: Europe | E6: TRUE | G6: 82904 | J6: 4040000000 | K6: 3790000000 | L6: 48671 | O6: 0.913 | P6: 84.041 | Q6: 14.54279 | R6: 11.61 | S6: 64631.075
A7: AO | B7: AGO | C7: Angola | D7: Africa | E7: TRUE | G7: 39040000 | J7: 113340000000 | K7: 90550000000 | L7: 2903 | M7: 2018 | N7: 0.51264286 | O7: 0.616 | P7: 64.617 | Q7: 12.1676 | R7: 5.956173 | S7: 6631.2765
A8: AI | C8: Anguilla | D8: North America | E8: FALSE | G8: 14728 | K8: 415740000 | L8: 28228
A9: AG | C9: Antigua and Barbuda | D9: North America | E9: TRUE | G9: 94209 | J9: 2370000000 | K9: 2030000000 | L9: 25189 | O9: 0.851 | P9: 77.598 | Q9: 15.502999 | R9: 11.6475 | S9: 27386.518
A10: AR | B10: ARG | C10: Argentina | D10: South America | E10: TRUE | F10: Peso | G10: 45851400 | H10: -14.6 | I10: 17 | J10: 683530000000 | K10: 646080000000 | L10: 14908 | M10: 2023 | N10: 0.42390975 | O10: 0.865 | P10: 77.395 | Q10: 18.831209 | R10: 11.184582 | S10: 25876.053 | T10: 38.3 | U10: 11.5 | V10: 26.6 | W10: 38.6 | X10: 43.1 | Y10: 48.3 | Z10: 15.2 | AA10: 4.8 | AB10: 4.6 | AC10: 20.8 | AD10: 21.9 | AE10: 996.2 | AF10: 0.1 | AG10: 122.1 | AH10: 49.3 | AI10: 36.7 | AJ10: 67.9 | AK10: 15.2 | AL10: 43.8 | AM10: 50.8 | AN10: 94.9 | AO10: 6.397
A11: AM | B11: ARM | C11: Armenia | D11: Asia | E11: TRUE | G11: 2952360 | J11: 26260000000 | K11: 24220000000 | L11: 8894 | M11: 2023 | N11: 0.2715465 | O11: 0.811 | P11: 75.683 | Q11: 14.38385 | R11: 11.344978 | S11: 20220.723 | T11: 40.5 | U11: 15.7 | V11: 29.7 | W11: 35.4 | X11: 40.3 | Y11: 41.6 | Z11: 20.9 | AA11: 4.4 | AB11: 6 | AC11: 22.5 | AD11: 16.5 | AE11: 340 | AF11: 0.3 | AG11: 120.2 | AH11: 42.7 | AI11: 77.6 | AJ11: 60 | AK11: 20.9 | AL11: 29.3 | AM11: 61.8 | AN11: 63.4 | AO11: 5.494
A12: AW | C12: Aruba | D12: North America | E12: FALSE | G12: 108147 | J12: 4100000000 | K12: 3650000000 | L12: 37911
A13: AU | B13: AUS | C13: Australia | D13: Oceania | E13: TRUE | F13: A$ | G13: 26974000 | H13: -13.2 | I13: -9.8 | J13: 1770000000000 | K13: 1780000000000 | L13: 65681 | M13: 2018 | N13: 0.34332526 | O13: 0.958 | P13: 83.923 | Q13: 20.654779 | R13: 12.87 | S13: 58276.876 | T13: 63 | U13: 32.1 | V13: 49.5 | W13: 71.1 | X13: 58.3 | Y13: 143.8 | Z13: 8.4 | AA13: 4.3 | AB13: 4.4 | AC13: 23.3 | AD13: 22.6 | AE13: 74 | AF13: 1.4 | AG13: 195.1 | AH13: 148.7 | AI13: 52.6 | AJ13: 73.1 | AK13: 8.4 | AL13: 37.4 | AM13: 26.9 | AN13: 94.2 | AO13: 6.974
A14: AT | B14: AUT | C14: Austria | D14: Europe | E14: TRUE | G14: 9113570 | J14: 534300000000 | K14: 511690000000 | L14: 58627 | M14: 2022 | N14: 0.3089293 | O14: 0.93 | P14: 81.956 | Q14: 16.284281 | R14: 12.361465 | S14: 63479.208 | T14: 67.6 | U14: 25 | V14: 49.1 | W14: 68.6 | X14: 63.6 | Y14: 118.9 | Z14: 11.8 | AA14: 2.8 | AB14: 3.1 | AC14: 35.3 | AD14: 32.7 | AE14: 83.4 | AF14: 1.2 | AG14: 197.7 | AH14: 122 | AI14: 71.7 | AJ14: 78.5 | AK14: 11.8 | AL14: 23.2 | AM14: 20.6 | AN14: 76.6 | AO14: 6.81
A15: AZ | C15: Azerbaijan | D15: Asia | E15: TRUE | F15: Manat | G15: 10397700 | H15: -36.8 | I15: -13.5 | J15: 78870000000 | K15: 72360000000 | L15: 7585 | O15: 0.789 | P15: 74.429 | Q15: 12.90978 | R15: 11.07 | S15: 20667.957 | T15: 29.3 | U15: 9.6 | V15: 20.7 | W15: 27.8 | X15: 32.6 | Y15: 44.1 | Z15: 16.8 | AA15: 4.9 | AB15: 5 | AC15: 20.4 | AD15: 19.9 | AE15: 180.6 | AF15: 0.6 | AG15: 114.4 | AH15: 45.1 | AI15: 68.2 | AJ15: 49.1 | AK15: 16.8 | AL15: 40.2 | AM15: 72 | AN15: 91.4 | AO15: 4.875
A16: BS | C16: Bahamas | D16: North America | E16: TRUE | G16: 403033 | J16: 15180000000 | K16: 14340000000 | L16: 37659 | O16: 0.82 | P16: 74.552 | Q16: 11.89138 | R16: 12.814419 | S16: 30974.681 | T16: 85.4 | U16: 47.1 | V16: 68.7 | W16: 88.7 | X16: 89.6 | Y16: 62.8
A17: BH | C17: Bahrain | D17: Asia | E17: TRUE | F17: Dinar | G17: 1643330 | H17: -20.6 | I17: -3.3 | J17: 47830000000 | K17: 44660000000 | L17: 29105 | O17: 0.899 | P17: 81.284 | Q17: 15.92719 | R17: 11.13 | S17: 52818.795 | T17: 46.1 | U17: 21.1 | V17: 35.2 | W17: 43.8 | X17: 43.8 | Y17: 125 | AO17: 6.03
A18: BD | B18: BGD | C18: Bangladesh | D18: Asia | E18: TRUE | G18: 175687000 | J18: 467220000000 | K18: 422430000000 | L18: 2659 | M18: 2022 | N18: 0.33373156 | O18: 0.685 | P18: 74.672 | Q18: 12.310168 | R18: 6.79 | S18: 8497.6586 | T18: 21.2 | U18: 2.4 | V18: 13 | W18: 25.6 | X18: 15.3 | Y18: 38.9 | Z18: 11.5 | AA18: 3.2 | AB18: 3.1 | AC18: 31.7 | AD18: 32.2 | AE18: 134.4 | AF18: 0.7 | AG18: 77 | AH18: 39.3 | AI18: 38.5 | AJ18: 41.7 | AK18: 11.5 | AL18: 56.5 | AM18: 85.6 | AN18: 72.9 | AO18: 3.851
A19: BB | B19: BRB | C19: Barbados | D19: North America | E19: TRUE | G19: 282623 | J19: 7550000000 | K19: 6720000000 | L19: 26721 | M19: 2016 | N19: 0.34068036 | O19: 0.811 | P19: 76.178 | Q19: 16.628002 | R19: 9.9283569 | S19: 17327.52
A20: BY | B20: BLR | C20: Belarus | D20: Europe | E20: TRUE | G20: 8997600 | J20: 71560000000 | K20: 71860000000 | L20: 7953 | M20: 2020 | N20: 0.24383356 | O20: 0.824 | P20: 74.434 | Q20: 13.71881 | R20: 12.335373 | S20: 26724.871 | T20: 25.3 | U20: 9.5 | V20: 18.4 | W20: 25.5 | X20: 25.9 | Y20: 65.7 | Z20: 12.6 | AA20: 5 | AB20: 5 | AC20: 20.1 | AD20: 19.9 | AE20: 200.3 | AF20: 0.5 | AG20: 134.8 | AH20: 67.4 | AI20: 50.9 | AJ20: 49.3 | AK20: 12.6 | AL20: 31.3 | AM20: 44.5 | AN20: 69.3
A21: BE | B21: BEL | C21: Belgium | D21: Europe | E21: TRUE | G21: 11758600 | J21: 684860000000 | K21: 644780000000 | L21: 58244 | M21: 2022 | N21: 0.26375556 | O21: 0.951 | P21: 82.115 | Q21: 18.996031 | R21: 12.68965 | S21: 63582.475 | T21: 63.6 | U21: 22.8 | V21: 45.9 | W21: 61.9 | X21: 71.4 | Y21: 127.7 | Z21: 6.6 | AA21: 4.7 | AB21: 5.1 | AC21: 21.4 | AD21: 19.6 | AE21: 46.6 | AF21: 2.1 | AG21: 173.7 | AH21: 131 | AI21: 50.5 | AJ21: 75.8 | AK21: 6.6 | AL21: 34.5 | AM21: 49.2 | AN21: 86.4 | AO21: 6.91
A22: BZ | B22: BLZ | C22: Belize | D22: North America | E22: TRUE | G22: 422924 | J22: 3610000000 | K22: 3080000000 | L22: 8538 | M22: 2018 | N22: 0.39949584 | O22: 0.721 | P22: 73.566 | Q22: 11.9838 | R22: 8.76229 | S22: 12343.078 | T22: 42.3 | U22: 10.2 | V22: 28.3 | W22: 47.5 | X22: 33.8 | Y22: 78 | AO22: 6.711
A23: BJ | B23: BEN | C23: Benin | D23: Africa | E23: TRUE | G23: 14814500 | J23: 22240000000 | K23: 19670000000 | L23: 1501 | M23: 2021 | N23: 0.34395808 | O23: 0.515 | P23: 60.774 | Q23: 10.44648 | R23: 3.1942 | S23: 3805.5275 | AO23: 4.357
A24: BM | C24: Bermuda | D24: North America | E24: FALSE | G24: 64555 | K24: 8140000000 | L24: 126120
A25: BT | B25: BTN | C25: Bhutan | D25: Asia | E25: TRUE | G25: 796682 | J25: 3420000000 | K25: 3020000000 | L25: 4295 | M25: 2022 | N25: 0.2845992 | O25: 0.698 | P25: 72.975 | Q25: 13.152742 | R25: 5.8357947 | S25: 13842.804
A26: BO | B26: BOL | C26: Bolivia | D26: South America | E26: TRUE | G26: 12581800 | J26: 56340000000 | K26: 45140000000 | L26: 4478 | M26: 2023 | N26: 0.42050114 | O26: 0.733 | P26: 68.581 | Q26: 15.61065 | R26: 10.021223 | S26: 9445.2449 | T26: 25.5 | U26: 8.6 | V26: 18.1 | W26: 26.6 | X26: 20.7 | Y26: 45.6 | Z26: 12.6 | AA26: 7 | AB26: 6.1 | AC26: 14.3 | AD26: 16.4 | AE26: 121.1 | AF26: 0.8 | AO26: 5.868
A27: BA | B27: BIH | C27: Bosnia and Herzegovina | D27: Europe | E27: TRUE | G27: 3140100 | J27: 28810000000 | K27: 27510000000 | L27: 9174 | M27: 2011 | N27: 0.33030185 | O27: 0.804 | P27: 77.85 | Q27: 13.16394 | R27: 10.97 | S27: 19827.486 | T27: 35.7 | U27: 7.3 | V27: 23.4 | W27: 36.7 | X27: 28.2 | Y27: 67.3 | Z27: 13.2 | AA27: 2.9 | AB27: 2.9 | AC27: 34.8 | AD27: 34.4 | AE27: 101.7 | AF27: 1 | AG27: 136.8 | AH27: 68.4 | AI27: 58.8 | AJ27: 54.9 | AK27: 13.2 | AL27: 25.9 | AM27: 59.7 | AN27: 82.9 | AO27: 6.136
A28: BW | B28: BWA | C28: Botswana | D28: Africa | E28: TRUE | G28: 2562120 | J28: 19400000000 | K28: 19400000000 | L28: 7572 | M28: 2015 | N28: 0.5490736 | O28: 0.731 | P28: 69.163 | Q28: 11.42568 | R28: 10.478 | S28: 16983.771 | T28: 41.7 | U28: 6.1 | V28: 26.2 | W28: 29.9 | X28: 26.6 | Y28: 72.1 | AO28: 3.438
A29: BR | B29: BRA | C29: Brazil | D29: South America | E29: TRUE | F29: Real | G29: 212812000 | H29: -28.4 | I29: -3.2 | J29: 2130000000000 | K29: 2190000000000 | L29: 9990 | M29: 2023 | N29: 0.5163944 | O29: 0.786 | P29: 75.848 | Q29: 15.79271 | R29: 8.4253718 | S29: 18011.285 | T29: 28.6 | U29: 8.2 | V29: 19.7 | W29: 29.1 | X29: 23.8 | Y29: 46.6 | Z29: 15.1 | AA29: 4.7 | AB29: 4.6 | AC29: 21.3 | AD29: 21.6 | AE29: 189.8 | AF29: 0.5 | AG29: 117.8 | AH29: 47.6 | AI29: 35.8 | AJ29: 59.2 | AK29: 15.1 | AL29: 40.5 | AM29: 52.8 | AN29: 91.8 | AO29: 6.494
A30: VG | C30: British Virgin Islands | D30: North America | E30: FALSE | G30: 39732 | K30: 1510000000 | L30: 37900
A31: BN | C31: Brunei | D31: Asia | E31: TRUE | G31: 466330 | J31: 16010000000 | K31: 15130000000 | L31: 34325 | O31: 0.837 | P31: 75.327 | Q31: 13.69862 | R31: 9.282 | S31: 75826.873 | T31: 46.1 | U31: 17 | V31: 33.4 | W31: 65.9 | X31: 29 | Y31: 136.8
A32: BG | B32: BGR | C32: Bulgaria | D32: Europe | E32: TRUE | G32: 6714560 | J32: 117010000000 | K32: 102400000000 | L32: 17426 | M32: 2022 | N32: 0.38201502 | O32: 0.845 | P32: 75.636 | Q32: 15.31664 | R32: 11.454531 | S32: 32174.93 | T32: 39.3 | U32: 11.7 | V32: 27.3 | W32: 40.5 | X32: 38.7 | Y32: 86.3 | Z32: 9.1 | AA32: 4.3 | AB32: 4.6 | AC32: 23.4 | AD32: 21.7 | AE32: 65.8 | AF32: 1.5 | AG32: 148.3 | AH32: 88.2 | AI32: 64.1 | AJ32: 58.2 | AK32: 9.1 | AL32: 29.1 | AM32: 62.8 | AN32: 81.5 | AO32: 5.554
A33: BF | B33: BFA | C33: Burkina Faso | D33: Africa | E33: TRUE | G33: 24074600 | J33: 27060000000 | K33: 20320000000 | L33: 1124 | M33: 2021 | N33: 0.37391287 | O33: 0.459 | P33: 61.092 | Q33: 8.7333403 | R33: 2.2665501 | S33: 2390.5278 | AO33: 4.383
A34: BI | B34: BDI | C34: Burundi | D34: Africa | E34: TRUE | G34: 14390000 | J34: 6750000000 | K34: 3960000000 | L34: 469 | M34: 2020 | N34: 0.37456086 | O34: 0.439 | P34: 63.651 | Q34: 9.8294239 | R34: 3.4739356 | S34: 858.91557
A35: KH | C35: Cambodia | D35: Asia | E35: TRUE | G35: 17848000 | J35: 49800000000 | K35: 42820000000 | L35: 2790 | O35: 0.606 | P35: 70.668 | Q35: 11.197892 | R35: 5.1971002 | S35: 4931.0168 | T35: 33 | U35: 9.1 | V35: 22.6 | W35: 40 | X35: 22.6 | Y35: 30.3 | AO35: 4.341
A36: CM | B36: CMR | C36: Cameroon | D36: Africa | E36: TRUE | G36: 29879300 | J36: 56010000000 | K36: 49280000000 | L36: 1875 | M36: 2021 | N36: 0.42176074 | O36: 0.588 | P36: 63.7 | Q36: 10.79188 | R36: 6.5741804 | S36: 4746.2658 | T36: 39.6 | U36: 18.7 | V36: 30.5 | W36: 36.5 | X36: 45.7 | Y36: 10.7 | Z36: 46.7 | AA36: 9.1 | AB36: 10.5 | AC36: 11 | AD36: 9.6 | AE36: 909.8 | AF36: 0.1 | AO36: 4.887
A37: CA | B37: CAN | C37: Canada | D37: North America | E37: TRUE | F37: C$ | G37: 40126700 | H37: -9 | I37: 0.4 | J37: 2230000000000 | K37: 2140000000000 | L37: 55458 | M37: 2020 | N37: 0.29851684 | O37: 0.939 | P37: 82.63 | Q37: 15.88826 | R37: 13.87 | S37: 54688.417 | T37: 60.7 | U37: 31.9 | V37: 48.1 | W37: 67.5 | X37: 59 | Y37: 119.4 | Z37: 9.4 | AA37: 4.4 | AB37: 5.3 | AC37: 22.8 | AD37: 18.8 | AE37: 83.3 | AF37: 1.2 | AG37: 170.5 | AH37: 123.6 | AI37: 54.2 | AJ37: 68.6 | AK37: 9.4 | AL37: 33.5 | AM37: 29.8 | AN37: 55.9 | AO37: 6.803
A38: CV | B38: CPV | C38: Cape Verde | D38: Africa | E38: TRUE | G38: 527326 | J38: 2790000000 | K38: 2590000000 | L38: 5283 | M38: 2015 | N38: 0.42381087 | O38: 0.668 | P38: 76.059 | Q38: 11.367097 | R38: 6.090039 | S38: 8165.3792
A39: KY | C39: Cayman Islands | D39: North America | E39: FALSE | G39: 75844 | K39: 7130000000 | L39: 93972 | T39: 108.2 | U39: 76.3 | V39: 94.3 | W39: 113.9 | X39: 96.6 | Y39: 149.7
A40: CF | B40: CAF | C40: Central African Republic | D40: Africa | E40: TRUE | G40: 5513280 | J40: 2930000000 | K40: 2560000000 | L40: 532 | M40: 2021 | N40: 0.43034458 | O40: 0.414 | P40: 57.408 | Q40: 7.4357678 | R40: 3.9894315 | S40: 1099.8607
...
